2020-07-29 14:03:45,465 INFO org.apache.hadoop.yarn.server.resourcemanager.ResourceManager: STARTUP_MSG: 
/************************************************************
STARTUP_MSG: Starting ResourceManager
STARTUP_MSG:   host = yagnasri-VirtualBox/127.0.1.1
STARTUP_MSG:   args = []
STARTUP_MSG:   version = 2.9.0
STARTUP_MSG:   build = https://git-wip-us.apache.org/repos/asf/hadoop.git -r 756ebc8394e473ac25feac05fa493f6d612e6c50; compiled by 'arsuresh' on 2017-11-13T23:15Z
STARTUP_MSG:   java = 11.0.8
************************************************************/
2020-07-29 14:03:45,487 INFO org.apache.hadoop.yarn.server.resourcemanager.ResourceManager: registered UNIX signal handlers for [TERM, HUP, INT]
2020-07-29 14:03:45,959 INFO org.apache.hadoop.conf.Configuration: found resource core-site.xml at file:/usr/local/hadoop/etc/hadoop/core-site.xml
2020-07-29 14:03:46,396 WARN org.apache.hadoop.util.NativeCodeLoader: Unable to load native-hadoop library for your platform... using builtin-java classes where applicable
2020-07-29 14:03:46,593 INFO org.apache.hadoop.security.Groups: clearing userToGroupsMap cache
2020-07-29 14:03:46,726 INFO org.apache.hadoop.conf.Configuration: found resource yarn-site.xml at file:/usr/local/hadoop/etc/hadoop/yarn-site.xml
2020-07-29 14:03:46,790 INFO org.apache.hadoop.yarn.event.AsyncDispatcher: Registering class org.apache.hadoop.yarn.server.resourcemanager.RMFatalEventType for class org.apache.hadoop.yarn.server.resourcemanager.ResourceManager$RMFatalEventDispatcher
2020-07-29 14:03:46,899 INFO org.apache.hadoop.yarn.server.resourcemanager.security.NMTokenSecretManagerInRM: NMTokenKeyRollingInterval: 86400000ms and NMTokenKeyActivationDelay: 900000ms
2020-07-29 14:03:46,905 INFO org.apache.hadoop.yarn.server.resourcemanager.security.RMContainerTokenSecretManager: ContainerTokenKeyRollingInterval: 86400000ms and ContainerTokenKeyActivationDelay: 900000ms
2020-07-29 14:03:46,918 INFO org.apache.hadoop.yarn.server.resourcemanager.security.AMRMTokenSecretManager: AMRMTokenKeyRollingInterval: 86400000ms and AMRMTokenKeyActivationDelay: 900000 ms
2020-07-29 14:03:47,018 INFO org.apache.hadoop.yarn.event.AsyncDispatcher: Registering class org.apache.hadoop.yarn.server.resourcemanager.recovery.RMStateStoreEventType for class org.apache.hadoop.yarn.server.resourcemanager.recovery.RMStateStore$ForwardingEventHandler
2020-07-29 14:03:47,028 INFO org.apache.hadoop.yarn.event.AsyncDispatcher: Registering class org.apache.hadoop.yarn.server.resourcemanager.NodesListManagerEventType for class org.apache.hadoop.yarn.server.resourcemanager.NodesListManager
2020-07-29 14:03:47,029 INFO org.apache.hadoop.yarn.server.resourcemanager.ResourceManager: Using Scheduler: org.apache.hadoop.yarn.server.resourcemanager.scheduler.capacity.CapacityScheduler
2020-07-29 14:03:47,075 INFO org.apache.hadoop.yarn.event.AsyncDispatcher: Registering class org.apache.hadoop.yarn.server.resourcemanager.scheduler.event.SchedulerEventType for class org.apache.hadoop.yarn.event.EventDispatcher
2020-07-29 14:03:47,076 INFO org.apache.hadoop.yarn.event.AsyncDispatcher: Registering class org.apache.hadoop.yarn.server.resourcemanager.rmapp.RMAppEventType for class org.apache.hadoop.yarn.server.resourcemanager.ResourceManager$ApplicationEventDispatcher
2020-07-29 14:03:47,077 INFO org.apache.hadoop.yarn.event.AsyncDispatcher: Registering class org.apache.hadoop.yarn.server.resourcemanager.rmapp.attempt.RMAppAttemptEventType for class org.apache.hadoop.yarn.server.resourcemanager.ResourceManager$ApplicationAttemptEventDispatcher
2020-07-29 14:03:47,081 INFO org.apache.hadoop.yarn.event.AsyncDispatcher: Registering class org.apache.hadoop.yarn.server.resourcemanager.rmnode.RMNodeEventType for class org.apache.hadoop.yarn.server.resourcemanager.ResourceManager$NodeEventDispatcher
2020-07-29 14:03:47,178 INFO org.apache.hadoop.metrics2.impl.MetricsConfig: loaded properties from hadoop-metrics2.properties
2020-07-29 14:03:47,533 INFO org.apache.hadoop.metrics2.impl.MetricsSystemImpl: Scheduled Metric snapshot period at 10 second(s).
2020-07-29 14:03:47,533 INFO org.apache.hadoop.metrics2.impl.MetricsSystemImpl: ResourceManager metrics system started
2020-07-29 14:03:47,567 INFO org.apache.hadoop.yarn.security.YarnAuthorizationProvider: org.apache.hadoop.yarn.security.ConfiguredYarnAuthorizer is instantiated.
2020-07-29 14:03:47,573 INFO org.apache.hadoop.yarn.event.AsyncDispatcher: Registering class org.apache.hadoop.yarn.server.resourcemanager.RMAppManagerEventType for class org.apache.hadoop.yarn.server.resourcemanager.RMAppManager
2020-07-29 14:03:47,584 INFO org.apache.hadoop.yarn.event.AsyncDispatcher: Registering class org.apache.hadoop.yarn.server.resourcemanager.amlauncher.AMLauncherEventType for class org.apache.hadoop.yarn.server.resourcemanager.amlauncher.ApplicationMasterLauncher
2020-07-29 14:03:47,595 INFO org.apache.hadoop.yarn.server.resourcemanager.RMNMInfo: Registered RMNMInfo MBean
2020-07-29 14:03:47,595 INFO org.apache.hadoop.yarn.server.resourcemanager.rmapp.monitor.RMAppLifetimeMonitor: Application lifelime monitor interval set to 3000 ms.
2020-07-29 14:03:47,687 INFO org.apache.hadoop.util.HostsFileReader: Refreshing hosts (include/exclude) list
2020-07-29 14:03:47,815 INFO org.apache.hadoop.conf.Configuration: found resource capacity-scheduler.xml at file:/usr/local/hadoop/etc/hadoop/capacity-scheduler.xml
2020-07-29 14:03:48,423 INFO org.apache.hadoop.yarn.server.resourcemanager.scheduler.capacity.CapacitySchedulerConfiguration: max alloc mb per queue for root is undefined
2020-07-29 14:03:48,423 INFO org.apache.hadoop.yarn.server.resourcemanager.scheduler.capacity.CapacitySchedulerConfiguration: max alloc vcore per queue for root is undefined
2020-07-29 14:03:48,528 INFO org.apache.hadoop.yarn.server.resourcemanager.scheduler.capacity.ParentQueue: root, capacity=1.0, absoluteCapacity=1.0, maxCapacity=1.0, absoluteMaxCapacity=1.0, state=RUNNING, acls=ADMINISTER_QUEUE:*SUBMIT_APP:*, labels=*,
, reservationsContinueLooking=true, orderingPolicy=utilization, priority=0
2020-07-29 14:03:48,528 INFO org.apache.hadoop.yarn.server.resourcemanager.scheduler.capacity.ParentQueue: Initialized parent-queue root name=root, fullname=root
2020-07-29 14:03:48,605 INFO org.apache.hadoop.yarn.server.resourcemanager.scheduler.capacity.CapacitySchedulerConfiguration: max alloc mb per queue for root.default is undefined
2020-07-29 14:03:48,605 INFO org.apache.hadoop.yarn.server.resourcemanager.scheduler.capacity.CapacitySchedulerConfiguration: max alloc vcore per queue for root.default is undefined
2020-07-29 14:03:48,629 INFO org.apache.hadoop.yarn.server.resourcemanager.scheduler.capacity.LeafQueue: Initializing default
capacity = 1.0 [= (float) configuredCapacity / 100 ]
absoluteCapacity = 1.0 [= parentAbsoluteCapacity * capacity ]
maxCapacity = 1.0 [= configuredMaxCapacity ]
absoluteMaxCapacity = 1.0 [= 1.0 maximumCapacity undefined, (parentAbsoluteMaxCapacity * maximumCapacity) / 100 otherwise ]
userLimit = 100 [= configuredUserLimit ]
userLimitFactor = 1.0 [= configuredUserLimitFactor ]
maxApplications = 10000 [= configuredMaximumSystemApplicationsPerQueue or (int)(configuredMaximumSystemApplications * absoluteCapacity)]
maxApplicationsPerUser = 10000 [= (int)(maxApplications * (userLimit / 100.0f) * userLimitFactor) ]
usedCapacity = 0.0 [= usedResourcesMemory / (clusterResourceMemory * absoluteCapacity)]
absoluteUsedCapacity = 0.0 [= usedResourcesMemory / clusterResourceMemory]
maxAMResourcePerQueuePercent = 0.1 [= configuredMaximumAMResourcePercent ]
minimumAllocationFactor = 0.875 [= (float)(maximumAllocationMemory - minimumAllocationMemory) / maximumAllocationMemory ]
maximumAllocation = <memory:8192, vCores:4> [= configuredMaxAllocation ]
numContainers = 0 [= currentNumContainers ]
state = RUNNING [= configuredState ]
acls = ADMINISTER_QUEUE:*SUBMIT_APP:* [= configuredAcls ]
nodeLocalityDelay = 40
rackLocalityAdditionalDelay = -1
labels=*,
reservationsContinueLooking = true
preemptionDisabled = true
defaultAppPriorityPerQueue = 0
priority = 0
maxLifetime = -1 seconds
defaultLifetime = -1 seconds
2020-07-29 14:03:48,629 INFO org.apache.hadoop.yarn.server.resourcemanager.scheduler.capacity.CapacitySchedulerQueueManager: Initialized queue: default: capacity=1.0, absoluteCapacity=1.0, usedResources=<memory:0, vCores:0>, usedCapacity=0.0, absoluteUsedCapacity=0.0, numApps=0, numContainers=0
2020-07-29 14:03:48,633 INFO org.apache.hadoop.yarn.server.resourcemanager.scheduler.capacity.CapacitySchedulerQueueManager: Initialized queue: root: numChildQueue= 1, capacity=1.0, absoluteCapacity=1.0, usedResources=<memory:0, vCores:0>usedCapacity=0.0, numApps=0, numContainers=0
2020-07-29 14:03:48,634 INFO org.apache.hadoop.yarn.server.resourcemanager.scheduler.capacity.CapacitySchedulerQueueManager: Initialized root queue root: numChildQueue= 1, capacity=1.0, absoluteCapacity=1.0, usedResources=<memory:0, vCores:0>usedCapacity=0.0, numApps=0, numContainers=0
2020-07-29 14:03:48,634 INFO org.apache.hadoop.yarn.server.resourcemanager.scheduler.capacity.CapacityScheduler: Initialized queue mappings, override: false
2020-07-29 14:03:48,635 INFO org.apache.hadoop.yarn.server.resourcemanager.scheduler.capacity.CapacityScheduler: Initialized CapacityScheduler with calculator=class org.apache.hadoop.yarn.util.resource.DefaultResourceCalculator, minimumAllocation=<<memory:1024, vCores:1>>, maximumAllocation=<<memory:8192, vCores:4>>, asynchronousScheduling=false, asyncScheduleInterval=5ms
2020-07-29 14:03:48,658 INFO org.apache.hadoop.conf.Configuration: dynamic-resources.xml not found
2020-07-29 14:03:48,670 INFO org.apache.hadoop.yarn.server.resourcemanager.AMSProcessingChain: Initializing AMS Processing chain. Root Processor=[org.apache.hadoop.yarn.server.resourcemanager.DefaultAMSProcessor].
2020-07-29 14:03:48,711 INFO org.apache.hadoop.yarn.server.resourcemanager.ResourceManager: TimelineServicePublisher is not configured
2020-07-29 14:03:48,712 INFO org.apache.hadoop.yarn.server.resourcemanager.ResourceManager: Transitioning to active state
2020-07-29 14:03:48,810 INFO org.apache.hadoop.yarn.server.resourcemanager.recovery.RMStateStore: Updating AMRMToken
2020-07-29 14:03:48,811 INFO org.apache.hadoop.yarn.server.resourcemanager.security.RMContainerTokenSecretManager: Rolling master-key for container-tokens
2020-07-29 14:03:48,812 INFO org.apache.hadoop.yarn.server.resourcemanager.security.NMTokenSecretManagerInRM: Rolling master-key for nm-tokens
2020-07-29 14:03:48,812 INFO org.apache.hadoop.security.token.delegation.AbstractDelegationTokenSecretManager: Updating the current master key for generating delegation tokens
2020-07-29 14:03:48,815 INFO org.apache.hadoop.yarn.server.resourcemanager.security.RMDelegationTokenSecretManager: storing master key with keyID 1
2020-07-29 14:03:48,815 INFO org.apache.hadoop.yarn.server.resourcemanager.recovery.RMStateStore: Storing RMDTMasterKey.
2020-07-29 14:03:48,836 INFO org.apache.hadoop.security.token.delegation.AbstractDelegationTokenSecretManager: Starting expired delegation token remover thread, tokenRemoverScanInterval=60 min(s)
2020-07-29 14:03:48,855 INFO org.apache.hadoop.yarn.event.AsyncDispatcher: Registering class org.apache.hadoop.yarn.nodelabels.event.NodeLabelsStoreEventType for class org.apache.hadoop.yarn.nodelabels.CommonNodeLabelsManager$ForwardingEventHandler
2020-07-29 14:03:48,869 INFO org.apache.hadoop.security.token.delegation.AbstractDelegationTokenSecretManager: Updating the current master key for generating delegation tokens
2020-07-29 14:03:48,870 INFO org.apache.hadoop.yarn.server.resourcemanager.security.RMDelegationTokenSecretManager: storing master key with keyID 2
2020-07-29 14:03:48,870 INFO org.apache.hadoop.yarn.server.resourcemanager.recovery.RMStateStore: Storing RMDTMasterKey.
2020-07-29 14:03:48,998 INFO org.apache.hadoop.ipc.CallQueueManager: Using callQueue: class java.util.concurrent.LinkedBlockingQueue queueCapacity: 5000 scheduler: class org.apache.hadoop.ipc.DefaultRpcScheduler
2020-07-29 14:03:49,058 INFO org.apache.hadoop.ipc.Server: Starting Socket Reader #1 for port 8031
2020-07-29 14:03:49,995 INFO org.apache.hadoop.yarn.factories.impl.pb.RpcServerFactoryPBImpl: Adding protocol org.apache.hadoop.yarn.server.api.ResourceTrackerPB to the server
2020-07-29 14:03:49,996 INFO org.apache.hadoop.ipc.Server: IPC Server Responder: starting
2020-07-29 14:03:50,012 INFO org.apache.hadoop.ipc.Server: IPC Server listener on 8031: starting
2020-07-29 14:03:50,230 INFO org.apache.hadoop.ipc.CallQueueManager: Using callQueue: class java.util.concurrent.LinkedBlockingQueue queueCapacity: 5000 scheduler: class org.apache.hadoop.ipc.DefaultRpcScheduler
2020-07-29 14:03:50,239 INFO org.apache.hadoop.util.JvmPauseMonitor: Starting JVM pause monitor
2020-07-29 14:03:50,275 INFO org.apache.hadoop.ipc.Server: Starting Socket Reader #1 for port 8030
2020-07-29 14:03:50,401 INFO org.apache.hadoop.yarn.factories.impl.pb.RpcServerFactoryPBImpl: Adding protocol org.apache.hadoop.yarn.api.ApplicationMasterProtocolPB to the server
2020-07-29 14:03:50,406 INFO org.apache.hadoop.ipc.Server: IPC Server Responder: starting
2020-07-29 14:03:50,458 INFO org.apache.hadoop.ipc.Server: IPC Server listener on 8030: starting
2020-07-29 14:03:50,662 INFO org.apache.hadoop.ipc.CallQueueManager: Using callQueue: class java.util.concurrent.LinkedBlockingQueue queueCapacity: 5000 scheduler: class org.apache.hadoop.ipc.DefaultRpcScheduler
2020-07-29 14:03:50,670 INFO org.apache.hadoop.ipc.Server: Starting Socket Reader #1 for port 8032
2020-07-29 14:03:50,704 INFO org.apache.hadoop.yarn.factories.impl.pb.RpcServerFactoryPBImpl: Adding protocol org.apache.hadoop.yarn.api.ApplicationClientProtocolPB to the server
2020-07-29 14:03:50,721 INFO org.apache.hadoop.ipc.Server: IPC Server Responder: starting
2020-07-29 14:03:50,753 INFO org.apache.hadoop.ipc.Server: IPC Server listener on 8032: starting
2020-07-29 14:03:50,830 INFO org.apache.hadoop.yarn.server.resourcemanager.ResourceManager: Transitioned to active state
2020-07-29 14:03:51,174 INFO org.mortbay.log: Logging to org.slf4j.impl.Log4jLoggerAdapter(org.mortbay.log) via org.mortbay.log.Slf4jLog
2020-07-29 14:03:51,210 INFO org.apache.hadoop.security.authentication.server.AuthenticationFilter: Unable to initialize FileSignerSecretProvider, falling back to use random secrets.
2020-07-29 14:03:51,246 INFO org.apache.hadoop.http.HttpRequestLog: Http request log for http.requests.resourcemanager is not defined
2020-07-29 14:03:51,279 INFO org.apache.hadoop.http.HttpServer2: Added global filter 'safety' (class=org.apache.hadoop.http.HttpServer2$QuotingInputFilter)
2020-07-29 14:03:51,315 INFO org.apache.hadoop.http.HttpServer2: Added filter RMAuthenticationFilter (class=org.apache.hadoop.yarn.server.security.http.RMAuthenticationFilter) to context cluster
2020-07-29 14:03:51,315 INFO org.apache.hadoop.http.HttpServer2: Added filter RMAuthenticationFilter (class=org.apache.hadoop.yarn.server.security.http.RMAuthenticationFilter) to context static
2020-07-29 14:03:51,318 INFO org.apache.hadoop.http.HttpServer2: Added filter RMAuthenticationFilter (class=org.apache.hadoop.yarn.server.security.http.RMAuthenticationFilter) to context logs
2020-07-29 14:03:51,321 INFO org.apache.hadoop.http.HttpServer2: Added filter static_user_filter (class=org.apache.hadoop.http.lib.StaticUserWebFilter$StaticUserFilter) to context cluster
2020-07-29 14:03:51,322 INFO org.apache.hadoop.http.HttpServer2: Added filter static_user_filter (class=org.apache.hadoop.http.lib.StaticUserWebFilter$StaticUserFilter) to context static
2020-07-29 14:03:51,324 INFO org.apache.hadoop.http.HttpServer2: Added filter static_user_filter (class=org.apache.hadoop.http.lib.StaticUserWebFilter$StaticUserFilter) to context logs
2020-07-29 14:03:51,352 INFO org.apache.hadoop.http.HttpServer2: adding path spec: /cluster/*
2020-07-29 14:03:51,356 INFO org.apache.hadoop.http.HttpServer2: adding path spec: /ws/*
2020-07-29 14:03:53,232 INFO org.apache.hadoop.yarn.webapp.WebApps: Registered webapp guice modules
2020-07-29 14:03:53,252 INFO org.apache.hadoop.http.HttpServer2: Jetty bound to port 8088
2020-07-29 14:03:53,252 INFO org.mortbay.log: jetty-6.1.26
2020-07-29 14:03:53,761 INFO org.mortbay.log: Extract jar:file:/usr/local/hadoop/share/hadoop/yarn/hadoop-yarn-common-2.9.0.jar!/webapps/cluster to /tmp/Jetty_0_0_0_0_8088_cluster____u0rgz3/webapp
2020-07-29 14:03:54,264 INFO org.apache.hadoop.security.token.delegation.AbstractDelegationTokenSecretManager: Updating the current master key for generating delegation tokens
2020-07-29 14:03:54,273 INFO org.apache.hadoop.security.token.delegation.AbstractDelegationTokenSecretManager: Starting expired delegation token remover thread, tokenRemoverScanInterval=60 min(s)
2020-07-29 14:03:54,285 INFO org.apache.hadoop.security.token.delegation.AbstractDelegationTokenSecretManager: Updating the current master key for generating delegation tokens
2020-07-29 14:03:59,149 INFO org.mortbay.log: Started HttpServer2$SelectChannelConnectorWithSafeStartup@0.0.0.0:8088
2020-07-29 14:03:59,149 INFO org.apache.hadoop.yarn.webapp.WebApps: Web app cluster started at 8088
2020-07-29 14:03:59,282 INFO org.apache.hadoop.ipc.CallQueueManager: Using callQueue: class java.util.concurrent.LinkedBlockingQueue queueCapacity: 100 scheduler: class org.apache.hadoop.ipc.DefaultRpcScheduler
2020-07-29 14:03:59,288 INFO org.apache.hadoop.ipc.Server: Starting Socket Reader #1 for port 8033
2020-07-29 14:03:59,346 INFO org.apache.hadoop.yarn.factories.impl.pb.RpcServerFactoryPBImpl: Adding protocol org.apache.hadoop.yarn.server.api.ResourceManagerAdministrationProtocolPB to the server
2020-07-29 14:03:59,351 INFO org.apache.hadoop.ipc.Server: IPC Server Responder: starting
2020-07-29 14:03:59,364 INFO org.apache.hadoop.ipc.Server: IPC Server listener on 8033: starting
2020-07-29 14:04:05,147 INFO org.apache.hadoop.yarn.server.resourcemanager.ResourceTrackerService: NodeManager from node yagnasri-VirtualBox(cmPort: 41987 httpPort: 8042) registered with capability: <memory:8192, vCores:8>, assigned nodeId yagnasri-VirtualBox:41987
2020-07-29 14:04:05,154 INFO org.apache.hadoop.yarn.server.resourcemanager.rmnode.RMNodeImpl: yagnasri-VirtualBox:41987 Node Transitioned from NEW to RUNNING
2020-07-29 14:04:05,183 INFO org.apache.hadoop.yarn.server.resourcemanager.scheduler.capacity.CapacityScheduler: Added node yagnasri-VirtualBox:41987 clusterResource: <memory:8192, vCores:8>
2020-07-29 14:13:47,813 INFO org.apache.hadoop.yarn.server.resourcemanager.scheduler.AbstractYarnScheduler: Release request cache is cleaned up
2020-07-29 19:16:22,257 INFO org.apache.hadoop.util.JvmPauseMonitor: Detected pause in JVM or host machine (eg GC): pause of approximately 1717ms
No GCs detected
2020-07-29 22:23:59,524 INFO org.apache.hadoop.yarn.server.resourcemanager.ClientRMService: Allocated new applicationId: 1
2020-07-29 22:24:01,635 INFO org.apache.hadoop.yarn.server.resourcemanager.scheduler.capacity.CapacityScheduler: Application 'application_1596049428713_0001' is submitted without priority hence considering default queue/cluster priority: 0
2020-07-29 22:24:01,635 INFO org.apache.hadoop.yarn.server.resourcemanager.scheduler.capacity.CapacityScheduler: Priority '0' is acceptable in queue : default for application: application_1596049428713_0001
2020-07-29 22:24:01,653 INFO org.apache.hadoop.yarn.server.resourcemanager.rmapp.RMAppImpl: Storing application with id application_1596049428713_0001
2020-07-29 22:24:01,659 INFO org.apache.hadoop.yarn.server.resourcemanager.recovery.RMStateStore: Storing info for app: application_1596049428713_0001
2020-07-29 22:24:01,659 INFO org.apache.hadoop.yarn.server.resourcemanager.ClientRMService: Application with id 1 submitted by user yagnasri
2020-07-29 22:24:01,660 INFO org.apache.hadoop.yarn.server.resourcemanager.RMAuditLogger: USER=yagnasri	IP=127.0.0.1	OPERATION=Submit Application Request	TARGET=ClientRMService	RESULT=SUCCESS	APPID=application_1596049428713_0001
2020-07-29 22:24:01,671 INFO org.apache.hadoop.yarn.server.resourcemanager.rmapp.RMAppImpl: application_1596049428713_0001 State change from NEW to NEW_SAVING on event = START
2020-07-29 22:24:01,671 INFO org.apache.hadoop.yarn.server.resourcemanager.rmapp.RMAppImpl: application_1596049428713_0001 State change from NEW_SAVING to SUBMITTED on event = APP_NEW_SAVED
2020-07-29 22:24:01,673 INFO org.apache.hadoop.yarn.server.resourcemanager.scheduler.capacity.ParentQueue: Application added - appId: application_1596049428713_0001 user: yagnasri leaf-queue of parent: root #applications: 1
2020-07-29 22:24:01,674 INFO org.apache.hadoop.yarn.server.resourcemanager.scheduler.capacity.CapacityScheduler: Accepted application application_1596049428713_0001 from user: yagnasri, in queue: default
2020-07-29 22:24:01,711 INFO org.apache.hadoop.yarn.server.resourcemanager.rmapp.RMAppImpl: application_1596049428713_0001 State change from SUBMITTED to ACCEPTED on event = APP_ACCEPTED
2020-07-29 22:24:01,773 INFO org.apache.hadoop.yarn.server.resourcemanager.ApplicationMasterService: Registering app attempt : appattempt_1596049428713_0001_000001
2020-07-29 22:24:01,778 INFO org.apache.hadoop.yarn.server.resourcemanager.rmapp.attempt.RMAppAttemptImpl: appattempt_1596049428713_0001_000001 State change from NEW to SUBMITTED on event = START
2020-07-29 22:24:01,807 WARN org.apache.hadoop.yarn.server.resourcemanager.scheduler.capacity.LeafQueue: maximum-am-resource-percent is insufficient to start a single application in queue, it is likely set too low. skipping enforcement to allow at least one application to start
2020-07-29 22:24:01,807 WARN org.apache.hadoop.yarn.server.resourcemanager.scheduler.capacity.LeafQueue: maximum-am-resource-percent is insufficient to start a single application in queue for user, it is likely set too low. skipping enforcement to allow at least one application to start
2020-07-29 22:24:01,813 INFO org.apache.hadoop.yarn.server.resourcemanager.scheduler.capacity.LeafQueue: Application application_1596049428713_0001 from user: yagnasri activated in queue: default
2020-07-29 22:24:01,813 INFO org.apache.hadoop.yarn.server.resourcemanager.scheduler.capacity.LeafQueue: Application added - appId: application_1596049428713_0001 user: yagnasri, leaf-queue: default #user-pending-applications: 0 #user-active-applications: 1 #queue-pending-applications: 0 #queue-active-applications: 1
2020-07-29 22:24:01,813 INFO org.apache.hadoop.yarn.server.resourcemanager.scheduler.capacity.CapacityScheduler: Added Application Attempt appattempt_1596049428713_0001_000001 to scheduler from user yagnasri in queue default
2020-07-29 22:24:01,819 INFO org.apache.hadoop.yarn.server.resourcemanager.rmapp.attempt.RMAppAttemptImpl: appattempt_1596049428713_0001_000001 State change from SUBMITTED to SCHEDULED on event = ATTEMPT_ADDED
2020-07-29 22:24:02,604 INFO org.apache.hadoop.yarn.server.resourcemanager.scheduler.capacity.allocator.AbstractContainerAllocator: assignedContainer application attempt=appattempt_1596049428713_0001_000001 container=null queue=org.apache.hadoop.yarn.server.resourcemanager.scheduler.capacity.allocator.RegularContainerAllocator@3512a09a clusterResource=<memory:8192, vCores:8> type=OFF_SWITCH requestedPartition=
2020-07-29 22:24:02,609 INFO org.apache.hadoop.yarn.server.resourcemanager.scheduler.capacity.ParentQueue: assignedContainer queue=root usedCapacity=0.0 absoluteUsedCapacity=0.0 used=<memory:0, vCores:0> cluster=<memory:8192, vCores:8>
2020-07-29 22:24:02,613 INFO org.apache.hadoop.yarn.server.resourcemanager.rmcontainer.RMContainerImpl: container_1596049428713_0001_01_000001 Container Transitioned from NEW to ALLOCATED
2020-07-29 22:24:02,620 INFO org.apache.hadoop.yarn.server.resourcemanager.RMAuditLogger: USER=yagnasri	OPERATION=AM Allocated Container	TARGET=SchedulerApp	RESULT=SUCCESS	APPID=application_1596049428713_0001	CONTAINERID=container_1596049428713_0001_01_000001	RESOURCE=<memory:2048, vCores:1>
2020-07-29 22:24:02,660 INFO org.apache.hadoop.yarn.server.resourcemanager.security.NMTokenSecretManagerInRM: Sending NMToken for nodeId : yagnasri-VirtualBox:41987 for container : container_1596049428713_0001_01_000001
2020-07-29 22:24:02,682 INFO org.apache.hadoop.yarn.server.resourcemanager.rmcontainer.RMContainerImpl: container_1596049428713_0001_01_000001 Container Transitioned from ALLOCATED to ACQUIRED
2020-07-29 22:24:02,688 INFO org.apache.hadoop.yarn.server.resourcemanager.scheduler.capacity.ParentQueue: assignedContainer queue=root usedCapacity=0.25 absoluteUsedCapacity=0.25 used=<memory:2048, vCores:1> cluster=<memory:8192, vCores:8>
2020-07-29 22:24:02,688 INFO org.apache.hadoop.yarn.server.resourcemanager.scheduler.capacity.CapacityScheduler: Allocation proposal accepted
2020-07-29 22:24:02,688 INFO org.apache.hadoop.yarn.server.resourcemanager.security.NMTokenSecretManagerInRM: Clear node set for appattempt_1596049428713_0001_000001
2020-07-29 22:24:02,688 INFO org.apache.hadoop.yarn.server.resourcemanager.rmapp.attempt.RMAppAttemptImpl: Storing attempt: AppId: application_1596049428713_0001 AttemptId: appattempt_1596049428713_0001_000001 MasterContainer: Container: [ContainerId: container_1596049428713_0001_01_000001, AllocationRequestId: 0, Version: 0, NodeId: yagnasri-VirtualBox:41987, NodeHttpAddress: yagnasri-VirtualBox:8042, Resource: <memory:2048, vCores:1>, Priority: 0, Token: Token { kind: ContainerToken, service: 127.0.1.1:41987 }, ExecutionType: GUARANTEED, ]
2020-07-29 22:24:02,714 INFO org.apache.hadoop.yarn.server.resourcemanager.rmapp.attempt.RMAppAttemptImpl: appattempt_1596049428713_0001_000001 State change from SCHEDULED to ALLOCATED_SAVING on event = CONTAINER_ALLOCATED
2020-07-29 22:24:02,719 INFO org.apache.hadoop.yarn.server.resourcemanager.rmapp.attempt.RMAppAttemptImpl: appattempt_1596049428713_0001_000001 State change from ALLOCATED_SAVING to ALLOCATED on event = ATTEMPT_NEW_SAVED
2020-07-29 22:24:02,733 INFO org.apache.hadoop.yarn.server.resourcemanager.amlauncher.AMLauncher: Launching masterappattempt_1596049428713_0001_000001
2020-07-29 22:24:02,817 INFO org.apache.hadoop.yarn.server.resourcemanager.amlauncher.AMLauncher: Setting up container Container: [ContainerId: container_1596049428713_0001_01_000001, AllocationRequestId: 0, Version: 0, NodeId: yagnasri-VirtualBox:41987, NodeHttpAddress: yagnasri-VirtualBox:8042, Resource: <memory:2048, vCores:1>, Priority: 0, Token: Token { kind: ContainerToken, service: 127.0.1.1:41987 }, ExecutionType: GUARANTEED, ] for AM appattempt_1596049428713_0001_000001
2020-07-29 22:24:02,824 INFO org.apache.hadoop.yarn.server.resourcemanager.security.AMRMTokenSecretManager: Create AMRMToken for ApplicationAttempt: appattempt_1596049428713_0001_000001
2020-07-29 22:24:02,828 INFO org.apache.hadoop.yarn.server.resourcemanager.security.AMRMTokenSecretManager: Creating password for appattempt_1596049428713_0001_000001
2020-07-29 22:24:03,754 INFO org.apache.hadoop.yarn.server.resourcemanager.rmcontainer.RMContainerImpl: container_1596049428713_0001_01_000001 Container Transitioned from ACQUIRED to RUNNING
2020-07-29 22:24:03,873 INFO org.apache.hadoop.yarn.server.resourcemanager.amlauncher.AMLauncher: Done launching container Container: [ContainerId: container_1596049428713_0001_01_000001, AllocationRequestId: 0, Version: 0, NodeId: yagnasri-VirtualBox:41987, NodeHttpAddress: yagnasri-VirtualBox:8042, Resource: <memory:2048, vCores:1>, Priority: 0, Token: Token { kind: ContainerToken, service: 127.0.1.1:41987 }, ExecutionType: GUARANTEED, ] for AM appattempt_1596049428713_0001_000001
2020-07-29 22:24:03,873 INFO org.apache.hadoop.yarn.server.resourcemanager.rmapp.attempt.RMAppAttemptImpl: appattempt_1596049428713_0001_000001 State change from ALLOCATED to LAUNCHED on event = LAUNCHED
2020-07-29 22:24:16,107 INFO SecurityLogger.org.apache.hadoop.ipc.Server: Auth successful for appattempt_1596049428713_0001_000001 (auth:SIMPLE)
2020-07-29 22:24:16,141 INFO org.apache.hadoop.yarn.server.resourcemanager.DefaultAMSProcessor: AM registration appattempt_1596049428713_0001_000001
2020-07-29 22:24:16,142 INFO org.apache.hadoop.yarn.server.resourcemanager.rmapp.attempt.RMAppAttemptImpl: appattempt_1596049428713_0001_000001 State change from LAUNCHED to RUNNING on event = REGISTERED
2020-07-29 22:24:16,142 INFO org.apache.hadoop.yarn.server.resourcemanager.rmapp.RMAppImpl: application_1596049428713_0001 State change from ACCEPTED to RUNNING on event = ATTEMPT_REGISTERED
2020-07-29 22:24:16,152 INFO org.apache.hadoop.yarn.server.resourcemanager.RMAuditLogger: USER=yagnasri	IP=127.0.0.1	OPERATION=Register App Master	TARGET=ApplicationMasterService	RESULT=SUCCESS	APPID=application_1596049428713_0001	APPATTEMPTID=appattempt_1596049428713_0001_000001
2020-07-29 22:24:17,813 INFO org.apache.hadoop.yarn.server.resourcemanager.scheduler.capacity.allocator.AbstractContainerAllocator: assignedContainer application attempt=appattempt_1596049428713_0001_000001 container=null queue=org.apache.hadoop.yarn.server.resourcemanager.scheduler.capacity.allocator.RegularContainerAllocator@3512a09a clusterResource=<memory:8192, vCores:8> type=NODE_LOCAL requestedPartition=
2020-07-29 22:24:17,814 INFO org.apache.hadoop.yarn.server.resourcemanager.scheduler.capacity.ParentQueue: assignedContainer queue=root usedCapacity=0.25 absoluteUsedCapacity=0.25 used=<memory:2048, vCores:1> cluster=<memory:8192, vCores:8>
2020-07-29 22:24:17,816 INFO org.apache.hadoop.yarn.server.resourcemanager.rmcontainer.RMContainerImpl: container_1596049428713_0001_01_000002 Container Transitioned from NEW to ALLOCATED
2020-07-29 22:24:17,816 INFO org.apache.hadoop.yarn.server.resourcemanager.RMAuditLogger: USER=yagnasri	OPERATION=AM Allocated Container	TARGET=SchedulerApp	RESULT=SUCCESS	APPID=application_1596049428713_0001	CONTAINERID=container_1596049428713_0001_01_000002	RESOURCE=<memory:1024, vCores:1>
2020-07-29 22:24:17,817 INFO org.apache.hadoop.yarn.server.resourcemanager.scheduler.capacity.ParentQueue: assignedContainer queue=root usedCapacity=0.375 absoluteUsedCapacity=0.375 used=<memory:3072, vCores:2> cluster=<memory:8192, vCores:8>
2020-07-29 22:24:17,817 INFO org.apache.hadoop.yarn.server.resourcemanager.scheduler.capacity.CapacityScheduler: Allocation proposal accepted
2020-07-29 22:24:17,820 INFO org.apache.hadoop.yarn.server.resourcemanager.scheduler.capacity.allocator.AbstractContainerAllocator: assignedContainer application attempt=appattempt_1596049428713_0001_000001 container=null queue=org.apache.hadoop.yarn.server.resourcemanager.scheduler.capacity.allocator.RegularContainerAllocator@3512a09a clusterResource=<memory:8192, vCores:8> type=NODE_LOCAL requestedPartition=
2020-07-29 22:24:17,821 INFO org.apache.hadoop.yarn.server.resourcemanager.scheduler.capacity.ParentQueue: assignedContainer queue=root usedCapacity=0.375 absoluteUsedCapacity=0.375 used=<memory:3072, vCores:2> cluster=<memory:8192, vCores:8>
2020-07-29 22:24:17,828 INFO org.apache.hadoop.yarn.server.resourcemanager.rmcontainer.RMContainerImpl: container_1596049428713_0001_01_000003 Container Transitioned from NEW to ALLOCATED
2020-07-29 22:24:17,829 INFO org.apache.hadoop.yarn.server.resourcemanager.RMAuditLogger: USER=yagnasri	OPERATION=AM Allocated Container	TARGET=SchedulerApp	RESULT=SUCCESS	APPID=application_1596049428713_0001	CONTAINERID=container_1596049428713_0001_01_000003	RESOURCE=<memory:1024, vCores:1>
2020-07-29 22:24:17,829 INFO org.apache.hadoop.yarn.server.resourcemanager.scheduler.capacity.ParentQueue: assignedContainer queue=root usedCapacity=0.5 absoluteUsedCapacity=0.5 used=<memory:4096, vCores:3> cluster=<memory:8192, vCores:8>
2020-07-29 22:24:17,829 INFO org.apache.hadoop.yarn.server.resourcemanager.scheduler.capacity.CapacityScheduler: Allocation proposal accepted
2020-07-29 22:24:18,264 INFO org.apache.hadoop.yarn.server.resourcemanager.security.NMTokenSecretManagerInRM: Sending NMToken for nodeId : yagnasri-VirtualBox:41987 for container : container_1596049428713_0001_01_000002
2020-07-29 22:24:18,279 INFO org.apache.hadoop.yarn.server.resourcemanager.rmcontainer.RMContainerImpl: container_1596049428713_0001_01_000002 Container Transitioned from ALLOCATED to ACQUIRED
2020-07-29 22:24:18,284 INFO org.apache.hadoop.yarn.server.resourcemanager.rmcontainer.RMContainerImpl: container_1596049428713_0001_01_000003 Container Transitioned from ALLOCATED to ACQUIRED
2020-07-29 22:24:18,813 INFO org.apache.hadoop.yarn.server.resourcemanager.rmcontainer.RMContainerImpl: container_1596049428713_0001_01_000002 Container Transitioned from ACQUIRED to RUNNING
2020-07-29 22:24:18,814 INFO org.apache.hadoop.yarn.server.resourcemanager.rmcontainer.RMContainerImpl: container_1596049428713_0001_01_000003 Container Transitioned from ACQUIRED to RUNNING
2020-07-29 22:24:19,332 INFO org.apache.hadoop.yarn.server.resourcemanager.scheduler.AppSchedulingInfo: checking for deactivate of application :application_1596049428713_0001
2020-07-29 22:24:33,372 INFO org.apache.hadoop.yarn.server.resourcemanager.rmcontainer.RMContainerImpl: container_1596049428713_0001_01_000003 Container Transitioned from RUNNING to COMPLETED
2020-07-29 22:24:33,373 INFO org.apache.hadoop.yarn.server.resourcemanager.RMAuditLogger: USER=yagnasri	OPERATION=AM Released Container	TARGET=SchedulerApp	RESULT=SUCCESS	APPID=application_1596049428713_0001	CONTAINERID=container_1596049428713_0001_01_000003	RESOURCE=<memory:1024, vCores:1>
2020-07-29 22:24:33,541 INFO org.apache.hadoop.yarn.server.resourcemanager.rmcontainer.RMContainerImpl: container_1596049428713_0001_01_000002 Container Transitioned from RUNNING to COMPLETED
2020-07-29 22:24:33,541 INFO org.apache.hadoop.yarn.server.resourcemanager.RMAuditLogger: USER=yagnasri	OPERATION=AM Released Container	TARGET=SchedulerApp	RESULT=SUCCESS	APPID=application_1596049428713_0001	CONTAINERID=container_1596049428713_0001_01_000002	RESOURCE=<memory:1024, vCores:1>
2020-07-29 22:24:34,550 INFO org.apache.hadoop.yarn.server.resourcemanager.scheduler.capacity.allocator.AbstractContainerAllocator: assignedContainer application attempt=appattempt_1596049428713_0001_000001 container=null queue=org.apache.hadoop.yarn.server.resourcemanager.scheduler.capacity.allocator.RegularContainerAllocator@3512a09a clusterResource=<memory:8192, vCores:8> type=OFF_SWITCH requestedPartition=
2020-07-29 22:24:34,551 INFO org.apache.hadoop.yarn.server.resourcemanager.scheduler.capacity.ParentQueue: assignedContainer queue=root usedCapacity=0.25 absoluteUsedCapacity=0.25 used=<memory:2048, vCores:1> cluster=<memory:8192, vCores:8>
2020-07-29 22:24:34,553 INFO org.apache.hadoop.yarn.server.resourcemanager.rmcontainer.RMContainerImpl: container_1596049428713_0001_01_000004 Container Transitioned from NEW to ALLOCATED
2020-07-29 22:24:34,553 INFO org.apache.hadoop.yarn.server.resourcemanager.RMAuditLogger: USER=yagnasri	OPERATION=AM Allocated Container	TARGET=SchedulerApp	RESULT=SUCCESS	APPID=application_1596049428713_0001	CONTAINERID=container_1596049428713_0001_01_000004	RESOURCE=<memory:1024, vCores:1>
2020-07-29 22:24:34,554 INFO org.apache.hadoop.yarn.server.resourcemanager.scheduler.capacity.ParentQueue: assignedContainer queue=root usedCapacity=0.375 absoluteUsedCapacity=0.375 used=<memory:3072, vCores:2> cluster=<memory:8192, vCores:8>
2020-07-29 22:24:34,555 INFO org.apache.hadoop.yarn.server.resourcemanager.scheduler.capacity.CapacityScheduler: Allocation proposal accepted
2020-07-29 22:24:35,466 INFO org.apache.hadoop.yarn.server.resourcemanager.rmcontainer.RMContainerImpl: container_1596049428713_0001_01_000004 Container Transitioned from ALLOCATED to ACQUIRED
2020-07-29 22:24:35,554 INFO org.apache.hadoop.yarn.server.resourcemanager.rmcontainer.RMContainerImpl: container_1596049428713_0001_01_000004 Container Transitioned from ACQUIRED to RUNNING
2020-07-29 22:24:36,474 INFO org.apache.hadoop.yarn.server.resourcemanager.scheduler.AppSchedulingInfo: checking for deactivate of application :application_1596049428713_0001
2020-07-29 22:24:42,420 INFO org.apache.hadoop.yarn.server.resourcemanager.rmapp.attempt.RMAppAttemptImpl: Updating application attempt appattempt_1596049428713_0001_000001 with final state: FINISHING, and exit status: -1000
2020-07-29 22:24:42,421 INFO org.apache.hadoop.yarn.server.resourcemanager.rmapp.attempt.RMAppAttemptImpl: appattempt_1596049428713_0001_000001 State change from RUNNING to FINAL_SAVING on event = UNREGISTERED
2020-07-29 22:24:42,421 INFO org.apache.hadoop.yarn.server.resourcemanager.rmapp.attempt.RMAppAttemptImpl: appattempt_1596049428713_0001_000001 State change from FINAL_SAVING to FINISHING on event = ATTEMPT_UPDATE_SAVED
2020-07-29 22:24:42,425 INFO org.apache.hadoop.yarn.server.resourcemanager.rmapp.RMAppImpl: Updating application application_1596049428713_0001 with final state: FINISHING
2020-07-29 22:24:42,425 INFO org.apache.hadoop.yarn.server.resourcemanager.recovery.RMStateStore: Updating info for app: application_1596049428713_0001
2020-07-29 22:24:42,426 INFO org.apache.hadoop.yarn.server.resourcemanager.rmapp.RMAppImpl: application_1596049428713_0001 State change from RUNNING to FINAL_SAVING on event = ATTEMPT_UNREGISTERED
2020-07-29 22:24:42,426 INFO org.apache.hadoop.yarn.server.resourcemanager.rmapp.RMAppImpl: application_1596049428713_0001 State change from FINAL_SAVING to FINISHING on event = APP_UPDATE_SAVED
2020-07-29 22:24:42,471 INFO org.apache.hadoop.yarn.server.resourcemanager.rmcontainer.RMContainerImpl: container_1596049428713_0001_01_000004 Container Transitioned from RUNNING to COMPLETED
2020-07-29 22:24:42,471 INFO org.apache.hadoop.yarn.server.resourcemanager.RMAuditLogger: USER=yagnasri	OPERATION=AM Released Container	TARGET=SchedulerApp	RESULT=SUCCESS	APPID=application_1596049428713_0001	CONTAINERID=container_1596049428713_0001_01_000004	RESOURCE=<memory:1024, vCores:1>
2020-07-29 22:24:43,438 INFO org.apache.hadoop.yarn.server.resourcemanager.ApplicationMasterService: application_1596049428713_0001 unregistered successfully. 
2020-07-29 22:24:48,902 INFO org.apache.hadoop.yarn.server.resourcemanager.rmcontainer.RMContainerImpl: container_1596049428713_0001_01_000001 Container Transitioned from RUNNING to COMPLETED
2020-07-29 22:24:48,903 INFO org.apache.hadoop.yarn.server.resourcemanager.RMAuditLogger: USER=yagnasri	OPERATION=AM Released Container	TARGET=SchedulerApp	RESULT=SUCCESS	APPID=application_1596049428713_0001	CONTAINERID=container_1596049428713_0001_01_000001	RESOURCE=<memory:2048, vCores:1>
2020-07-29 22:24:48,903 INFO org.apache.hadoop.yarn.server.resourcemanager.ApplicationMasterService: Unregistering app attempt : appattempt_1596049428713_0001_000001
2020-07-29 22:24:48,904 INFO org.apache.hadoop.yarn.server.resourcemanager.security.AMRMTokenSecretManager: Application finished, removing password for appattempt_1596049428713_0001_000001
2020-07-29 22:24:48,904 INFO org.apache.hadoop.yarn.server.resourcemanager.rmapp.attempt.RMAppAttemptImpl: appattempt_1596049428713_0001_000001 State change from FINISHING to FINISHED on event = CONTAINER_FINISHED
2020-07-29 22:24:48,906 INFO org.apache.hadoop.yarn.server.resourcemanager.rmapp.RMAppImpl: application_1596049428713_0001 State change from FINISHING to FINISHED on event = ATTEMPT_FINISHED
2020-07-29 22:24:48,906 INFO org.apache.hadoop.yarn.server.resourcemanager.scheduler.capacity.CapacityScheduler: Application Attempt appattempt_1596049428713_0001_000001 is done. finalState=FINISHED
2020-07-29 22:24:48,906 INFO org.apache.hadoop.yarn.server.resourcemanager.scheduler.AppSchedulingInfo: Application application_1596049428713_0001 requests cleared
2020-07-29 22:24:48,906 INFO org.apache.hadoop.yarn.server.resourcemanager.scheduler.capacity.LeafQueue: Application removed - appId: application_1596049428713_0001 user: yagnasri queue: default #user-pending-applications: 0 #user-active-applications: 0 #queue-pending-applications: 0 #queue-active-applications: 0
2020-07-29 22:24:48,909 INFO org.apache.hadoop.yarn.server.resourcemanager.scheduler.capacity.ParentQueue: Application removed - appId: application_1596049428713_0001 user: yagnasri leaf-queue of parent: root #applications: 0
2020-07-29 22:24:48,910 INFO org.apache.hadoop.yarn.server.resourcemanager.RMAuditLogger: USER=yagnasri	OPERATION=Application Finished - Succeeded	TARGET=RMAppManager	RESULT=SUCCESS	APPID=application_1596049428713_0001
2020-07-29 22:24:48,919 INFO org.apache.hadoop.yarn.server.resourcemanager.RMAppManager$ApplicationSummary: appId=application_1596049428713_0001,name=word count,user=yagnasri,queue=default,state=FINISHED,trackingUrl=http://yagnasri-VirtualBox:8088/proxy/application_1596049428713_0001/,appMasterHost=yagnasri-VirtualBox,submitTime=1596079441576,startTime=1596079441649,finishTime=1596079482425,finalStatus=SUCCEEDED,memorySeconds=134980,vcoreSeconds=83,preemptedMemorySeconds=0,preemptedVcoreSeconds=0,preemptedAMContainers=0,preemptedNonAMContainers=0,preemptedResources=<memory:0\, vCores:0>,applicationType=MAPREDUCE
2020-07-29 22:24:48,919 INFO org.apache.hadoop.yarn.server.resourcemanager.amlauncher.AMLauncher: Cleaning master appattempt_1596049428713_0001_000001
2020-07-29 22:34:47,551 INFO org.apache.hadoop.yarn.server.resourcemanager.ClientRMService: Allocated new applicationId: 2
2020-07-29 22:34:49,299 INFO org.apache.hadoop.yarn.server.resourcemanager.scheduler.capacity.CapacityScheduler: Application 'application_1596049428713_0002' is submitted without priority hence considering default queue/cluster priority: 0
2020-07-29 22:34:49,299 INFO org.apache.hadoop.yarn.server.resourcemanager.scheduler.capacity.CapacityScheduler: Priority '0' is acceptable in queue : default for application: application_1596049428713_0002
2020-07-29 22:34:49,299 INFO org.apache.hadoop.yarn.server.resourcemanager.ClientRMService: Application with id 2 submitted by user yagnasri
2020-07-29 22:34:49,299 INFO org.apache.hadoop.yarn.server.resourcemanager.RMAuditLogger: USER=yagnasri	IP=127.0.0.1	OPERATION=Submit Application Request	TARGET=ClientRMService	RESULT=SUCCESS	APPID=application_1596049428713_0002
2020-07-29 22:34:49,299 INFO org.apache.hadoop.yarn.server.resourcemanager.rmapp.RMAppImpl: Storing application with id application_1596049428713_0002
2020-07-29 22:34:49,300 INFO org.apache.hadoop.yarn.server.resourcemanager.rmapp.RMAppImpl: application_1596049428713_0002 State change from NEW to NEW_SAVING on event = START
2020-07-29 22:34:49,300 INFO org.apache.hadoop.yarn.server.resourcemanager.recovery.RMStateStore: Storing info for app: application_1596049428713_0002
2020-07-29 22:34:49,300 INFO org.apache.hadoop.yarn.server.resourcemanager.rmapp.RMAppImpl: application_1596049428713_0002 State change from NEW_SAVING to SUBMITTED on event = APP_NEW_SAVED
2020-07-29 22:34:49,300 INFO org.apache.hadoop.yarn.server.resourcemanager.scheduler.capacity.ParentQueue: Application added - appId: application_1596049428713_0002 user: yagnasri leaf-queue of parent: root #applications: 1
2020-07-29 22:34:49,300 INFO org.apache.hadoop.yarn.server.resourcemanager.scheduler.capacity.CapacityScheduler: Accepted application application_1596049428713_0002 from user: yagnasri, in queue: default
2020-07-29 22:34:49,301 INFO org.apache.hadoop.yarn.server.resourcemanager.rmapp.RMAppImpl: application_1596049428713_0002 State change from SUBMITTED to ACCEPTED on event = APP_ACCEPTED
2020-07-29 22:34:49,301 INFO org.apache.hadoop.yarn.server.resourcemanager.ApplicationMasterService: Registering app attempt : appattempt_1596049428713_0002_000001
2020-07-29 22:34:49,301 INFO org.apache.hadoop.yarn.server.resourcemanager.rmapp.attempt.RMAppAttemptImpl: appattempt_1596049428713_0002_000001 State change from NEW to SUBMITTED on event = START
2020-07-29 22:34:49,301 WARN org.apache.hadoop.yarn.server.resourcemanager.scheduler.capacity.LeafQueue: maximum-am-resource-percent is insufficient to start a single application in queue, it is likely set too low. skipping enforcement to allow at least one application to start
2020-07-29 22:34:49,301 WARN org.apache.hadoop.yarn.server.resourcemanager.scheduler.capacity.LeafQueue: maximum-am-resource-percent is insufficient to start a single application in queue for user, it is likely set too low. skipping enforcement to allow at least one application to start
2020-07-29 22:34:49,301 INFO org.apache.hadoop.yarn.server.resourcemanager.scheduler.capacity.LeafQueue: Application application_1596049428713_0002 from user: yagnasri activated in queue: default
2020-07-29 22:34:49,301 INFO org.apache.hadoop.yarn.server.resourcemanager.scheduler.capacity.LeafQueue: Application added - appId: application_1596049428713_0002 user: yagnasri, leaf-queue: default #user-pending-applications: 0 #user-active-applications: 1 #queue-pending-applications: 0 #queue-active-applications: 1
2020-07-29 22:34:49,301 INFO org.apache.hadoop.yarn.server.resourcemanager.scheduler.capacity.CapacityScheduler: Added Application Attempt appattempt_1596049428713_0002_000001 to scheduler from user yagnasri in queue default
2020-07-29 22:34:49,303 INFO org.apache.hadoop.yarn.server.resourcemanager.rmapp.attempt.RMAppAttemptImpl: appattempt_1596049428713_0002_000001 State change from SUBMITTED to SCHEDULED on event = ATTEMPT_ADDED
2020-07-29 22:34:50,029 INFO org.apache.hadoop.yarn.server.resourcemanager.scheduler.capacity.allocator.AbstractContainerAllocator: assignedContainer application attempt=appattempt_1596049428713_0002_000001 container=null queue=org.apache.hadoop.yarn.server.resourcemanager.scheduler.capacity.allocator.RegularContainerAllocator@234a3a1f clusterResource=<memory:8192, vCores:8> type=OFF_SWITCH requestedPartition=
2020-07-29 22:34:50,030 INFO org.apache.hadoop.yarn.server.resourcemanager.scheduler.capacity.ParentQueue: assignedContainer queue=root usedCapacity=0.0 absoluteUsedCapacity=0.0 used=<memory:0, vCores:0> cluster=<memory:8192, vCores:8>
2020-07-29 22:34:50,036 INFO org.apache.hadoop.yarn.server.resourcemanager.rmcontainer.RMContainerImpl: container_1596049428713_0002_01_000001 Container Transitioned from NEW to ALLOCATED
2020-07-29 22:34:50,037 INFO org.apache.hadoop.yarn.server.resourcemanager.RMAuditLogger: USER=yagnasri	OPERATION=AM Allocated Container	TARGET=SchedulerApp	RESULT=SUCCESS	APPID=application_1596049428713_0002	CONTAINERID=container_1596049428713_0002_01_000001	RESOURCE=<memory:2048, vCores:1>
2020-07-29 22:34:50,051 INFO org.apache.hadoop.yarn.server.resourcemanager.security.NMTokenSecretManagerInRM: Sending NMToken for nodeId : yagnasri-VirtualBox:41987 for container : container_1596049428713_0002_01_000001
2020-07-29 22:34:50,054 INFO org.apache.hadoop.yarn.server.resourcemanager.rmcontainer.RMContainerImpl: container_1596049428713_0002_01_000001 Container Transitioned from ALLOCATED to ACQUIRED
2020-07-29 22:34:50,055 INFO org.apache.hadoop.yarn.server.resourcemanager.scheduler.capacity.ParentQueue: assignedContainer queue=root usedCapacity=0.25 absoluteUsedCapacity=0.25 used=<memory:2048, vCores:1> cluster=<memory:8192, vCores:8>
2020-07-29 22:34:50,055 INFO org.apache.hadoop.yarn.server.resourcemanager.scheduler.capacity.CapacityScheduler: Allocation proposal accepted
2020-07-29 22:34:50,055 INFO org.apache.hadoop.yarn.server.resourcemanager.security.NMTokenSecretManagerInRM: Clear node set for appattempt_1596049428713_0002_000001
2020-07-29 22:34:50,055 INFO org.apache.hadoop.yarn.server.resourcemanager.rmapp.attempt.RMAppAttemptImpl: Storing attempt: AppId: application_1596049428713_0002 AttemptId: appattempt_1596049428713_0002_000001 MasterContainer: Container: [ContainerId: container_1596049428713_0002_01_000001, AllocationRequestId: 0, Version: 0, NodeId: yagnasri-VirtualBox:41987, NodeHttpAddress: yagnasri-VirtualBox:8042, Resource: <memory:2048, vCores:1>, Priority: 0, Token: Token { kind: ContainerToken, service: 127.0.1.1:41987 }, ExecutionType: GUARANTEED, ]
2020-07-29 22:34:50,056 INFO org.apache.hadoop.yarn.server.resourcemanager.rmapp.attempt.RMAppAttemptImpl: appattempt_1596049428713_0002_000001 State change from SCHEDULED to ALLOCATED_SAVING on event = CONTAINER_ALLOCATED
2020-07-29 22:34:50,056 INFO org.apache.hadoop.yarn.server.resourcemanager.rmapp.attempt.RMAppAttemptImpl: appattempt_1596049428713_0002_000001 State change from ALLOCATED_SAVING to ALLOCATED on event = ATTEMPT_NEW_SAVED
2020-07-29 22:34:50,058 INFO org.apache.hadoop.yarn.server.resourcemanager.amlauncher.AMLauncher: Launching masterappattempt_1596049428713_0002_000001
2020-07-29 22:34:50,067 INFO org.apache.hadoop.yarn.server.resourcemanager.amlauncher.AMLauncher: Setting up container Container: [ContainerId: container_1596049428713_0002_01_000001, AllocationRequestId: 0, Version: 0, NodeId: yagnasri-VirtualBox:41987, NodeHttpAddress: yagnasri-VirtualBox:8042, Resource: <memory:2048, vCores:1>, Priority: 0, Token: Token { kind: ContainerToken, service: 127.0.1.1:41987 }, ExecutionType: GUARANTEED, ] for AM appattempt_1596049428713_0002_000001
2020-07-29 22:34:50,067 INFO org.apache.hadoop.yarn.server.resourcemanager.security.AMRMTokenSecretManager: Create AMRMToken for ApplicationAttempt: appattempt_1596049428713_0002_000001
2020-07-29 22:34:50,068 INFO org.apache.hadoop.yarn.server.resourcemanager.security.AMRMTokenSecretManager: Creating password for appattempt_1596049428713_0002_000001
2020-07-29 22:34:50,113 INFO org.apache.hadoop.yarn.server.resourcemanager.amlauncher.AMLauncher: Done launching container Container: [ContainerId: container_1596049428713_0002_01_000001, AllocationRequestId: 0, Version: 0, NodeId: yagnasri-VirtualBox:41987, NodeHttpAddress: yagnasri-VirtualBox:8042, Resource: <memory:2048, vCores:1>, Priority: 0, Token: Token { kind: ContainerToken, service: 127.0.1.1:41987 }, ExecutionType: GUARANTEED, ] for AM appattempt_1596049428713_0002_000001
2020-07-29 22:34:50,113 INFO org.apache.hadoop.yarn.server.resourcemanager.rmapp.attempt.RMAppAttemptImpl: appattempt_1596049428713_0002_000001 State change from ALLOCATED to LAUNCHED on event = LAUNCHED
2020-07-29 22:34:51,028 INFO org.apache.hadoop.yarn.server.resourcemanager.rmcontainer.RMContainerImpl: container_1596049428713_0002_01_000001 Container Transitioned from ACQUIRED to RUNNING
2020-07-29 22:34:59,815 INFO SecurityLogger.org.apache.hadoop.ipc.Server: Auth successful for appattempt_1596049428713_0002_000001 (auth:SIMPLE)
2020-07-29 22:34:59,827 INFO org.apache.hadoop.yarn.server.resourcemanager.DefaultAMSProcessor: AM registration appattempt_1596049428713_0002_000001
2020-07-29 22:34:59,827 INFO org.apache.hadoop.yarn.server.resourcemanager.RMAuditLogger: USER=yagnasri	IP=127.0.0.1	OPERATION=Register App Master	TARGET=ApplicationMasterService	RESULT=SUCCESS	APPID=application_1596049428713_0002	APPATTEMPTID=appattempt_1596049428713_0002_000001
2020-07-29 22:34:59,828 INFO org.apache.hadoop.yarn.server.resourcemanager.rmapp.attempt.RMAppAttemptImpl: appattempt_1596049428713_0002_000001 State change from LAUNCHED to RUNNING on event = REGISTERED
2020-07-29 22:34:59,828 INFO org.apache.hadoop.yarn.server.resourcemanager.rmapp.RMAppImpl: application_1596049428713_0002 State change from ACCEPTED to RUNNING on event = ATTEMPT_REGISTERED
2020-07-29 22:35:01,044 INFO org.apache.hadoop.yarn.server.resourcemanager.scheduler.capacity.allocator.AbstractContainerAllocator: assignedContainer application attempt=appattempt_1596049428713_0002_000001 container=null queue=org.apache.hadoop.yarn.server.resourcemanager.scheduler.capacity.allocator.RegularContainerAllocator@234a3a1f clusterResource=<memory:8192, vCores:8> type=NODE_LOCAL requestedPartition=
2020-07-29 22:35:01,044 INFO org.apache.hadoop.yarn.server.resourcemanager.scheduler.capacity.ParentQueue: assignedContainer queue=root usedCapacity=0.25 absoluteUsedCapacity=0.25 used=<memory:2048, vCores:1> cluster=<memory:8192, vCores:8>
2020-07-29 22:35:01,045 INFO org.apache.hadoop.yarn.server.resourcemanager.rmcontainer.RMContainerImpl: container_1596049428713_0002_01_000002 Container Transitioned from NEW to ALLOCATED
2020-07-29 22:35:01,045 INFO org.apache.hadoop.yarn.server.resourcemanager.RMAuditLogger: USER=yagnasri	OPERATION=AM Allocated Container	TARGET=SchedulerApp	RESULT=SUCCESS	APPID=application_1596049428713_0002	CONTAINERID=container_1596049428713_0002_01_000002	RESOURCE=<memory:1024, vCores:1>
2020-07-29 22:35:01,045 INFO org.apache.hadoop.yarn.server.resourcemanager.scheduler.capacity.ParentQueue: assignedContainer queue=root usedCapacity=0.375 absoluteUsedCapacity=0.375 used=<memory:3072, vCores:2> cluster=<memory:8192, vCores:8>
2020-07-29 22:35:01,045 INFO org.apache.hadoop.yarn.server.resourcemanager.scheduler.capacity.CapacityScheduler: Allocation proposal accepted
2020-07-29 22:35:01,046 INFO org.apache.hadoop.yarn.server.resourcemanager.scheduler.capacity.allocator.AbstractContainerAllocator: assignedContainer application attempt=appattempt_1596049428713_0002_000001 container=null queue=org.apache.hadoop.yarn.server.resourcemanager.scheduler.capacity.allocator.RegularContainerAllocator@234a3a1f clusterResource=<memory:8192, vCores:8> type=NODE_LOCAL requestedPartition=
2020-07-29 22:35:01,046 INFO org.apache.hadoop.yarn.server.resourcemanager.scheduler.capacity.ParentQueue: assignedContainer queue=root usedCapacity=0.375 absoluteUsedCapacity=0.375 used=<memory:3072, vCores:2> cluster=<memory:8192, vCores:8>
2020-07-29 22:35:01,046 INFO org.apache.hadoop.yarn.server.resourcemanager.rmcontainer.RMContainerImpl: container_1596049428713_0002_01_000003 Container Transitioned from NEW to ALLOCATED
2020-07-29 22:35:01,046 INFO org.apache.hadoop.yarn.server.resourcemanager.RMAuditLogger: USER=yagnasri	OPERATION=AM Allocated Container	TARGET=SchedulerApp	RESULT=SUCCESS	APPID=application_1596049428713_0002	CONTAINERID=container_1596049428713_0002_01_000003	RESOURCE=<memory:1024, vCores:1>
2020-07-29 22:35:01,046 INFO org.apache.hadoop.yarn.server.resourcemanager.scheduler.capacity.ParentQueue: assignedContainer queue=root usedCapacity=0.5 absoluteUsedCapacity=0.5 used=<memory:4096, vCores:3> cluster=<memory:8192, vCores:8>
2020-07-29 22:35:01,046 INFO org.apache.hadoop.yarn.server.resourcemanager.scheduler.capacity.CapacityScheduler: Allocation proposal accepted
2020-07-29 22:35:01,975 INFO org.apache.hadoop.yarn.server.resourcemanager.security.NMTokenSecretManagerInRM: Sending NMToken for nodeId : yagnasri-VirtualBox:41987 for container : container_1596049428713_0002_01_000002
2020-07-29 22:35:01,979 INFO org.apache.hadoop.yarn.server.resourcemanager.rmcontainer.RMContainerImpl: container_1596049428713_0002_01_000002 Container Transitioned from ALLOCATED to ACQUIRED
2020-07-29 22:35:01,988 INFO org.apache.hadoop.yarn.server.resourcemanager.rmcontainer.RMContainerImpl: container_1596049428713_0002_01_000003 Container Transitioned from ALLOCATED to ACQUIRED
2020-07-29 22:35:03,030 INFO org.apache.hadoop.yarn.server.resourcemanager.scheduler.AppSchedulingInfo: checking for deactivate of application :application_1596049428713_0002
2020-07-29 22:35:03,051 INFO org.apache.hadoop.yarn.server.resourcemanager.rmcontainer.RMContainerImpl: container_1596049428713_0002_01_000002 Container Transitioned from ACQUIRED to RUNNING
2020-07-29 22:35:03,052 INFO org.apache.hadoop.yarn.server.resourcemanager.rmcontainer.RMContainerImpl: container_1596049428713_0002_01_000003 Container Transitioned from ACQUIRED to RUNNING
2020-07-29 22:35:16,706 INFO org.apache.hadoop.yarn.server.resourcemanager.rmcontainer.RMContainerImpl: container_1596049428713_0002_01_000003 Container Transitioned from RUNNING to COMPLETED
2020-07-29 22:35:16,706 INFO org.apache.hadoop.yarn.server.resourcemanager.RMAuditLogger: USER=yagnasri	OPERATION=AM Released Container	TARGET=SchedulerApp	RESULT=SUCCESS	APPID=application_1596049428713_0002	CONTAINERID=container_1596049428713_0002_01_000003	RESOURCE=<memory:1024, vCores:1>
2020-07-29 22:35:17,124 INFO org.apache.hadoop.yarn.server.resourcemanager.rmcontainer.RMContainerImpl: container_1596049428713_0002_01_000002 Container Transitioned from RUNNING to COMPLETED
2020-07-29 22:35:17,124 INFO org.apache.hadoop.yarn.server.resourcemanager.RMAuditLogger: USER=yagnasri	OPERATION=AM Released Container	TARGET=SchedulerApp	RESULT=SUCCESS	APPID=application_1596049428713_0002	CONTAINERID=container_1596049428713_0002_01_000002	RESOURCE=<memory:1024, vCores:1>
2020-07-29 22:35:19,139 INFO org.apache.hadoop.yarn.server.resourcemanager.scheduler.capacity.allocator.AbstractContainerAllocator: assignedContainer application attempt=appattempt_1596049428713_0002_000001 container=null queue=org.apache.hadoop.yarn.server.resourcemanager.scheduler.capacity.allocator.RegularContainerAllocator@234a3a1f clusterResource=<memory:8192, vCores:8> type=OFF_SWITCH requestedPartition=
2020-07-29 22:35:19,140 INFO org.apache.hadoop.yarn.server.resourcemanager.scheduler.capacity.ParentQueue: assignedContainer queue=root usedCapacity=0.25 absoluteUsedCapacity=0.25 used=<memory:2048, vCores:1> cluster=<memory:8192, vCores:8>
2020-07-29 22:35:19,140 INFO org.apache.hadoop.yarn.server.resourcemanager.rmcontainer.RMContainerImpl: container_1596049428713_0002_01_000004 Container Transitioned from NEW to ALLOCATED
2020-07-29 22:35:19,140 INFO org.apache.hadoop.yarn.server.resourcemanager.RMAuditLogger: USER=yagnasri	OPERATION=AM Allocated Container	TARGET=SchedulerApp	RESULT=SUCCESS	APPID=application_1596049428713_0002	CONTAINERID=container_1596049428713_0002_01_000004	RESOURCE=<memory:1024, vCores:1>
2020-07-29 22:35:19,141 INFO org.apache.hadoop.yarn.server.resourcemanager.scheduler.capacity.ParentQueue: assignedContainer queue=root usedCapacity=0.375 absoluteUsedCapacity=0.375 used=<memory:3072, vCores:2> cluster=<memory:8192, vCores:8>
2020-07-29 22:35:19,141 INFO org.apache.hadoop.yarn.server.resourcemanager.scheduler.capacity.CapacityScheduler: Allocation proposal accepted
2020-07-29 22:35:19,185 INFO org.apache.hadoop.yarn.server.resourcemanager.rmcontainer.RMContainerImpl: container_1596049428713_0002_01_000004 Container Transitioned from ALLOCATED to ACQUIRED
2020-07-29 22:35:20,141 INFO org.apache.hadoop.yarn.server.resourcemanager.rmcontainer.RMContainerImpl: container_1596049428713_0002_01_000004 Container Transitioned from ACQUIRED to RUNNING
2020-07-29 22:35:20,191 INFO org.apache.hadoop.yarn.server.resourcemanager.scheduler.AppSchedulingInfo: checking for deactivate of application :application_1596049428713_0002
2020-07-29 22:35:26,195 INFO org.apache.hadoop.yarn.server.resourcemanager.rmcontainer.RMContainerImpl: container_1596049428713_0002_01_000004 Container Transitioned from RUNNING to COMPLETED
2020-07-29 22:35:26,195 INFO org.apache.hadoop.yarn.server.resourcemanager.RMAuditLogger: USER=yagnasri	OPERATION=AM Released Container	TARGET=SchedulerApp	RESULT=SUCCESS	APPID=application_1596049428713_0002	CONTAINERID=container_1596049428713_0002_01_000004	RESOURCE=<memory:1024, vCores:1>
2020-07-29 22:35:26,537 INFO org.apache.hadoop.yarn.server.resourcemanager.rmapp.attempt.RMAppAttemptImpl: Updating application attempt appattempt_1596049428713_0002_000001 with final state: FINISHING, and exit status: -1000
2020-07-29 22:35:26,537 INFO org.apache.hadoop.yarn.server.resourcemanager.rmapp.attempt.RMAppAttemptImpl: appattempt_1596049428713_0002_000001 State change from RUNNING to FINAL_SAVING on event = UNREGISTERED
2020-07-29 22:35:26,537 INFO org.apache.hadoop.yarn.server.resourcemanager.rmapp.RMAppImpl: Updating application application_1596049428713_0002 with final state: FINISHING
2020-07-29 22:35:26,537 INFO org.apache.hadoop.yarn.server.resourcemanager.rmapp.RMAppImpl: application_1596049428713_0002 State change from RUNNING to FINAL_SAVING on event = ATTEMPT_UNREGISTERED
2020-07-29 22:35:26,537 INFO org.apache.hadoop.yarn.server.resourcemanager.recovery.RMStateStore: Updating info for app: application_1596049428713_0002
2020-07-29 22:35:26,537 INFO org.apache.hadoop.yarn.server.resourcemanager.rmapp.attempt.RMAppAttemptImpl: appattempt_1596049428713_0002_000001 State change from FINAL_SAVING to FINISHING on event = ATTEMPT_UPDATE_SAVED
2020-07-29 22:35:26,537 INFO org.apache.hadoop.yarn.server.resourcemanager.rmapp.RMAppImpl: application_1596049428713_0002 State change from FINAL_SAVING to FINISHING on event = APP_UPDATE_SAVED
2020-07-29 22:35:27,552 INFO org.apache.hadoop.yarn.server.resourcemanager.ApplicationMasterService: application_1596049428713_0002 unregistered successfully. 
2020-07-29 22:35:33,045 INFO org.apache.hadoop.yarn.server.resourcemanager.rmcontainer.RMContainerImpl: container_1596049428713_0002_01_000001 Container Transitioned from RUNNING to COMPLETED
2020-07-29 22:35:33,045 INFO org.apache.hadoop.yarn.server.resourcemanager.RMAuditLogger: USER=yagnasri	OPERATION=AM Released Container	TARGET=SchedulerApp	RESULT=SUCCESS	APPID=application_1596049428713_0002	CONTAINERID=container_1596049428713_0002_01_000001	RESOURCE=<memory:2048, vCores:1>
2020-07-29 22:35:33,045 INFO org.apache.hadoop.yarn.server.resourcemanager.ApplicationMasterService: Unregistering app attempt : appattempt_1596049428713_0002_000001
2020-07-29 22:35:33,046 INFO org.apache.hadoop.yarn.server.resourcemanager.security.AMRMTokenSecretManager: Application finished, removing password for appattempt_1596049428713_0002_000001
2020-07-29 22:35:33,046 INFO org.apache.hadoop.yarn.server.resourcemanager.rmapp.attempt.RMAppAttemptImpl: appattempt_1596049428713_0002_000001 State change from FINISHING to FINISHED on event = CONTAINER_FINISHED
2020-07-29 22:35:33,046 INFO org.apache.hadoop.yarn.server.resourcemanager.rmapp.RMAppImpl: application_1596049428713_0002 State change from FINISHING to FINISHED on event = ATTEMPT_FINISHED
2020-07-29 22:35:33,046 INFO org.apache.hadoop.yarn.server.resourcemanager.RMAuditLogger: USER=yagnasri	OPERATION=Application Finished - Succeeded	TARGET=RMAppManager	RESULT=SUCCESS	APPID=application_1596049428713_0002
2020-07-29 22:35:33,047 INFO org.apache.hadoop.yarn.server.resourcemanager.RMAppManager$ApplicationSummary: appId=application_1596049428713_0002,name=word count,user=yagnasri,queue=default,state=FINISHED,trackingUrl=http://yagnasri-VirtualBox:8088/proxy/application_1596049428713_0002/,appMasterHost=yagnasri-VirtualBox,submitTime=1596080089299,startTime=1596080089299,finishTime=1596080126537,finalStatus=SUCCEEDED,memorySeconds=127821,vcoreSeconds=81,preemptedMemorySeconds=0,preemptedVcoreSeconds=0,preemptedAMContainers=0,preemptedNonAMContainers=0,preemptedResources=<memory:0\, vCores:0>,applicationType=MAPREDUCE
2020-07-29 22:35:33,047 INFO org.apache.hadoop.yarn.server.resourcemanager.scheduler.capacity.CapacityScheduler: Application Attempt appattempt_1596049428713_0002_000001 is done. finalState=FINISHED
2020-07-29 22:35:33,047 INFO org.apache.hadoop.yarn.server.resourcemanager.scheduler.AppSchedulingInfo: Application application_1596049428713_0002 requests cleared
2020-07-29 22:35:33,047 INFO org.apache.hadoop.yarn.server.resourcemanager.scheduler.capacity.LeafQueue: Application removed - appId: application_1596049428713_0002 user: yagnasri queue: default #user-pending-applications: 0 #user-active-applications: 0 #queue-pending-applications: 0 #queue-active-applications: 0
2020-07-29 22:35:33,047 INFO org.apache.hadoop.yarn.server.resourcemanager.scheduler.capacity.ParentQueue: Application removed - appId: application_1596049428713_0002 user: yagnasri leaf-queue of parent: root #applications: 0
2020-07-29 22:35:33,047 INFO org.apache.hadoop.yarn.server.resourcemanager.amlauncher.AMLauncher: Cleaning master appattempt_1596049428713_0002_000001
2020-07-29 22:37:35,881 INFO org.apache.hadoop.yarn.server.resourcemanager.ClientRMService: Allocated new applicationId: 3
2020-07-29 22:37:37,708 INFO org.apache.hadoop.yarn.server.resourcemanager.scheduler.capacity.CapacityScheduler: Application 'application_1596049428713_0003' is submitted without priority hence considering default queue/cluster priority: 0
2020-07-29 22:37:37,708 INFO org.apache.hadoop.yarn.server.resourcemanager.scheduler.capacity.CapacityScheduler: Priority '0' is acceptable in queue : default for application: application_1596049428713_0003
2020-07-29 22:37:37,709 INFO org.apache.hadoop.yarn.server.resourcemanager.ClientRMService: Application with id 3 submitted by user yagnasri
2020-07-29 22:37:37,709 INFO org.apache.hadoop.yarn.server.resourcemanager.RMAuditLogger: USER=yagnasri	IP=127.0.0.1	OPERATION=Submit Application Request	TARGET=ClientRMService	RESULT=SUCCESS	APPID=application_1596049428713_0003
2020-07-29 22:37:37,709 INFO org.apache.hadoop.yarn.server.resourcemanager.rmapp.RMAppImpl: Storing application with id application_1596049428713_0003
2020-07-29 22:37:37,709 INFO org.apache.hadoop.yarn.server.resourcemanager.rmapp.RMAppImpl: application_1596049428713_0003 State change from NEW to NEW_SAVING on event = START
2020-07-29 22:37:37,709 INFO org.apache.hadoop.yarn.server.resourcemanager.recovery.RMStateStore: Storing info for app: application_1596049428713_0003
2020-07-29 22:37:37,709 INFO org.apache.hadoop.yarn.server.resourcemanager.rmapp.RMAppImpl: application_1596049428713_0003 State change from NEW_SAVING to SUBMITTED on event = APP_NEW_SAVED
2020-07-29 22:37:37,710 INFO org.apache.hadoop.yarn.server.resourcemanager.scheduler.capacity.ParentQueue: Application added - appId: application_1596049428713_0003 user: yagnasri leaf-queue of parent: root #applications: 1
2020-07-29 22:37:37,710 INFO org.apache.hadoop.yarn.server.resourcemanager.scheduler.capacity.CapacityScheduler: Accepted application application_1596049428713_0003 from user: yagnasri, in queue: default
2020-07-29 22:37:37,710 INFO org.apache.hadoop.yarn.server.resourcemanager.rmapp.RMAppImpl: application_1596049428713_0003 State change from SUBMITTED to ACCEPTED on event = APP_ACCEPTED
2020-07-29 22:37:37,710 INFO org.apache.hadoop.yarn.server.resourcemanager.ApplicationMasterService: Registering app attempt : appattempt_1596049428713_0003_000001
2020-07-29 22:37:37,710 INFO org.apache.hadoop.yarn.server.resourcemanager.rmapp.attempt.RMAppAttemptImpl: appattempt_1596049428713_0003_000001 State change from NEW to SUBMITTED on event = START
2020-07-29 22:37:37,710 WARN org.apache.hadoop.yarn.server.resourcemanager.scheduler.capacity.LeafQueue: maximum-am-resource-percent is insufficient to start a single application in queue, it is likely set too low. skipping enforcement to allow at least one application to start
2020-07-29 22:37:37,710 WARN org.apache.hadoop.yarn.server.resourcemanager.scheduler.capacity.LeafQueue: maximum-am-resource-percent is insufficient to start a single application in queue for user, it is likely set too low. skipping enforcement to allow at least one application to start
2020-07-29 22:37:37,710 INFO org.apache.hadoop.yarn.server.resourcemanager.scheduler.capacity.LeafQueue: Application application_1596049428713_0003 from user: yagnasri activated in queue: default
2020-07-29 22:37:37,710 INFO org.apache.hadoop.yarn.server.resourcemanager.scheduler.capacity.LeafQueue: Application added - appId: application_1596049428713_0003 user: yagnasri, leaf-queue: default #user-pending-applications: 0 #user-active-applications: 1 #queue-pending-applications: 0 #queue-active-applications: 1
2020-07-29 22:37:37,710 INFO org.apache.hadoop.yarn.server.resourcemanager.scheduler.capacity.CapacityScheduler: Added Application Attempt appattempt_1596049428713_0003_000001 to scheduler from user yagnasri in queue default
2020-07-29 22:37:37,712 INFO org.apache.hadoop.yarn.server.resourcemanager.rmapp.attempt.RMAppAttemptImpl: appattempt_1596049428713_0003_000001 State change from SUBMITTED to SCHEDULED on event = ATTEMPT_ADDED
2020-07-29 22:37:38,257 INFO org.apache.hadoop.yarn.server.resourcemanager.scheduler.capacity.allocator.AbstractContainerAllocator: assignedContainer application attempt=appattempt_1596049428713_0003_000001 container=null queue=org.apache.hadoop.yarn.server.resourcemanager.scheduler.capacity.allocator.RegularContainerAllocator@301b8437 clusterResource=<memory:8192, vCores:8> type=OFF_SWITCH requestedPartition=
2020-07-29 22:37:38,258 INFO org.apache.hadoop.yarn.server.resourcemanager.scheduler.capacity.ParentQueue: assignedContainer queue=root usedCapacity=0.0 absoluteUsedCapacity=0.0 used=<memory:0, vCores:0> cluster=<memory:8192, vCores:8>
2020-07-29 22:37:38,260 INFO org.apache.hadoop.yarn.server.resourcemanager.rmcontainer.RMContainerImpl: container_1596049428713_0003_01_000001 Container Transitioned from NEW to ALLOCATED
2020-07-29 22:37:38,260 INFO org.apache.hadoop.yarn.server.resourcemanager.RMAuditLogger: USER=yagnasri	OPERATION=AM Allocated Container	TARGET=SchedulerApp	RESULT=SUCCESS	APPID=application_1596049428713_0003	CONTAINERID=container_1596049428713_0003_01_000001	RESOURCE=<memory:2048, vCores:1>
2020-07-29 22:37:38,262 INFO org.apache.hadoop.yarn.server.resourcemanager.security.NMTokenSecretManagerInRM: Sending NMToken for nodeId : yagnasri-VirtualBox:41987 for container : container_1596049428713_0003_01_000001
2020-07-29 22:37:38,264 INFO org.apache.hadoop.yarn.server.resourcemanager.rmcontainer.RMContainerImpl: container_1596049428713_0003_01_000001 Container Transitioned from ALLOCATED to ACQUIRED
2020-07-29 22:37:38,265 INFO org.apache.hadoop.yarn.server.resourcemanager.scheduler.capacity.ParentQueue: assignedContainer queue=root usedCapacity=0.25 absoluteUsedCapacity=0.25 used=<memory:2048, vCores:1> cluster=<memory:8192, vCores:8>
2020-07-29 22:37:38,265 INFO org.apache.hadoop.yarn.server.resourcemanager.scheduler.capacity.CapacityScheduler: Allocation proposal accepted
2020-07-29 22:37:38,265 INFO org.apache.hadoop.yarn.server.resourcemanager.security.NMTokenSecretManagerInRM: Clear node set for appattempt_1596049428713_0003_000001
2020-07-29 22:37:38,265 INFO org.apache.hadoop.yarn.server.resourcemanager.rmapp.attempt.RMAppAttemptImpl: Storing attempt: AppId: application_1596049428713_0003 AttemptId: appattempt_1596049428713_0003_000001 MasterContainer: Container: [ContainerId: container_1596049428713_0003_01_000001, AllocationRequestId: 0, Version: 0, NodeId: yagnasri-VirtualBox:41987, NodeHttpAddress: yagnasri-VirtualBox:8042, Resource: <memory:2048, vCores:1>, Priority: 0, Token: Token { kind: ContainerToken, service: 127.0.1.1:41987 }, ExecutionType: GUARANTEED, ]
2020-07-29 22:37:38,266 INFO org.apache.hadoop.yarn.server.resourcemanager.rmapp.attempt.RMAppAttemptImpl: appattempt_1596049428713_0003_000001 State change from SCHEDULED to ALLOCATED_SAVING on event = CONTAINER_ALLOCATED
2020-07-29 22:37:38,266 INFO org.apache.hadoop.yarn.server.resourcemanager.rmapp.attempt.RMAppAttemptImpl: appattempt_1596049428713_0003_000001 State change from ALLOCATED_SAVING to ALLOCATED on event = ATTEMPT_NEW_SAVED
2020-07-29 22:37:38,272 INFO org.apache.hadoop.yarn.server.resourcemanager.amlauncher.AMLauncher: Launching masterappattempt_1596049428713_0003_000001
2020-07-29 22:37:38,283 INFO org.apache.hadoop.yarn.server.resourcemanager.amlauncher.AMLauncher: Setting up container Container: [ContainerId: container_1596049428713_0003_01_000001, AllocationRequestId: 0, Version: 0, NodeId: yagnasri-VirtualBox:41987, NodeHttpAddress: yagnasri-VirtualBox:8042, Resource: <memory:2048, vCores:1>, Priority: 0, Token: Token { kind: ContainerToken, service: 127.0.1.1:41987 }, ExecutionType: GUARANTEED, ] for AM appattempt_1596049428713_0003_000001
2020-07-29 22:37:38,283 INFO org.apache.hadoop.yarn.server.resourcemanager.security.AMRMTokenSecretManager: Create AMRMToken for ApplicationAttempt: appattempt_1596049428713_0003_000001
2020-07-29 22:37:38,283 INFO org.apache.hadoop.yarn.server.resourcemanager.security.AMRMTokenSecretManager: Creating password for appattempt_1596049428713_0003_000001
2020-07-29 22:37:38,343 INFO org.apache.hadoop.yarn.server.resourcemanager.amlauncher.AMLauncher: Done launching container Container: [ContainerId: container_1596049428713_0003_01_000001, AllocationRequestId: 0, Version: 0, NodeId: yagnasri-VirtualBox:41987, NodeHttpAddress: yagnasri-VirtualBox:8042, Resource: <memory:2048, vCores:1>, Priority: 0, Token: Token { kind: ContainerToken, service: 127.0.1.1:41987 }, ExecutionType: GUARANTEED, ] for AM appattempt_1596049428713_0003_000001
2020-07-29 22:37:38,343 INFO org.apache.hadoop.yarn.server.resourcemanager.rmapp.attempt.RMAppAttemptImpl: appattempt_1596049428713_0003_000001 State change from ALLOCATED to LAUNCHED on event = LAUNCHED
2020-07-29 22:37:39,258 INFO org.apache.hadoop.yarn.server.resourcemanager.rmcontainer.RMContainerImpl: container_1596049428713_0003_01_000001 Container Transitioned from ACQUIRED to RUNNING
2020-07-29 22:37:47,144 INFO SecurityLogger.org.apache.hadoop.ipc.Server: Auth successful for appattempt_1596049428713_0003_000001 (auth:SIMPLE)
2020-07-29 22:37:47,152 INFO org.apache.hadoop.yarn.server.resourcemanager.DefaultAMSProcessor: AM registration appattempt_1596049428713_0003_000001
2020-07-29 22:37:47,152 INFO org.apache.hadoop.yarn.server.resourcemanager.RMAuditLogger: USER=yagnasri	IP=127.0.0.1	OPERATION=Register App Master	TARGET=ApplicationMasterService	RESULT=SUCCESS	APPID=application_1596049428713_0003	APPATTEMPTID=appattempt_1596049428713_0003_000001
2020-07-29 22:37:47,153 INFO org.apache.hadoop.yarn.server.resourcemanager.rmapp.attempt.RMAppAttemptImpl: appattempt_1596049428713_0003_000001 State change from LAUNCHED to RUNNING on event = REGISTERED
2020-07-29 22:37:47,153 INFO org.apache.hadoop.yarn.server.resourcemanager.rmapp.RMAppImpl: application_1596049428713_0003 State change from ACCEPTED to RUNNING on event = ATTEMPT_REGISTERED
2020-07-29 22:37:48,273 INFO org.apache.hadoop.yarn.server.resourcemanager.scheduler.capacity.allocator.AbstractContainerAllocator: assignedContainer application attempt=appattempt_1596049428713_0003_000001 container=null queue=org.apache.hadoop.yarn.server.resourcemanager.scheduler.capacity.allocator.RegularContainerAllocator@301b8437 clusterResource=<memory:8192, vCores:8> type=NODE_LOCAL requestedPartition=
2020-07-29 22:37:48,273 INFO org.apache.hadoop.yarn.server.resourcemanager.scheduler.capacity.ParentQueue: assignedContainer queue=root usedCapacity=0.25 absoluteUsedCapacity=0.25 used=<memory:2048, vCores:1> cluster=<memory:8192, vCores:8>
2020-07-29 22:37:48,273 INFO org.apache.hadoop.yarn.server.resourcemanager.rmcontainer.RMContainerImpl: container_1596049428713_0003_01_000002 Container Transitioned from NEW to ALLOCATED
2020-07-29 22:37:48,273 INFO org.apache.hadoop.yarn.server.resourcemanager.RMAuditLogger: USER=yagnasri	OPERATION=AM Allocated Container	TARGET=SchedulerApp	RESULT=SUCCESS	APPID=application_1596049428713_0003	CONTAINERID=container_1596049428713_0003_01_000002	RESOURCE=<memory:1024, vCores:1>
2020-07-29 22:37:48,274 INFO org.apache.hadoop.yarn.server.resourcemanager.scheduler.capacity.ParentQueue: assignedContainer queue=root usedCapacity=0.375 absoluteUsedCapacity=0.375 used=<memory:3072, vCores:2> cluster=<memory:8192, vCores:8>
2020-07-29 22:37:48,274 INFO org.apache.hadoop.yarn.server.resourcemanager.scheduler.capacity.CapacityScheduler: Allocation proposal accepted
2020-07-29 22:37:49,254 INFO org.apache.hadoop.yarn.server.resourcemanager.security.NMTokenSecretManagerInRM: Sending NMToken for nodeId : yagnasri-VirtualBox:41987 for container : container_1596049428713_0003_01_000002
2020-07-29 22:37:49,260 INFO org.apache.hadoop.yarn.server.resourcemanager.rmcontainer.RMContainerImpl: container_1596049428713_0003_01_000002 Container Transitioned from ALLOCATED to ACQUIRED
2020-07-29 22:37:50,278 INFO org.apache.hadoop.yarn.server.resourcemanager.rmcontainer.RMContainerImpl: container_1596049428713_0003_01_000002 Container Transitioned from ACQUIRED to RUNNING
2020-07-29 22:37:50,303 INFO org.apache.hadoop.yarn.server.resourcemanager.scheduler.AppSchedulingInfo: checking for deactivate of application :application_1596049428713_0003
2020-07-29 22:37:56,524 INFO org.apache.hadoop.yarn.server.resourcemanager.rmcontainer.RMContainerImpl: container_1596049428713_0003_01_000002 Container Transitioned from RUNNING to COMPLETED
2020-07-29 22:37:56,524 INFO org.apache.hadoop.yarn.server.resourcemanager.RMAuditLogger: USER=yagnasri	OPERATION=AM Released Container	TARGET=SchedulerApp	RESULT=SUCCESS	APPID=application_1596049428713_0003	CONTAINERID=container_1596049428713_0003_01_000002	RESOURCE=<memory:1024, vCores:1>
2020-07-29 22:37:57,529 INFO org.apache.hadoop.yarn.server.resourcemanager.scheduler.capacity.allocator.AbstractContainerAllocator: assignedContainer application attempt=appattempt_1596049428713_0003_000001 container=null queue=org.apache.hadoop.yarn.server.resourcemanager.scheduler.capacity.allocator.RegularContainerAllocator@301b8437 clusterResource=<memory:8192, vCores:8> type=OFF_SWITCH requestedPartition=
2020-07-29 22:37:57,529 INFO org.apache.hadoop.yarn.server.resourcemanager.scheduler.capacity.ParentQueue: assignedContainer queue=root usedCapacity=0.25 absoluteUsedCapacity=0.25 used=<memory:2048, vCores:1> cluster=<memory:8192, vCores:8>
2020-07-29 22:37:57,530 INFO org.apache.hadoop.yarn.server.resourcemanager.rmcontainer.RMContainerImpl: container_1596049428713_0003_01_000003 Container Transitioned from NEW to ALLOCATED
2020-07-29 22:37:57,530 INFO org.apache.hadoop.yarn.server.resourcemanager.RMAuditLogger: USER=yagnasri	OPERATION=AM Allocated Container	TARGET=SchedulerApp	RESULT=SUCCESS	APPID=application_1596049428713_0003	CONTAINERID=container_1596049428713_0003_01_000003	RESOURCE=<memory:1024, vCores:1>
2020-07-29 22:37:57,531 INFO org.apache.hadoop.yarn.server.resourcemanager.scheduler.capacity.ParentQueue: assignedContainer queue=root usedCapacity=0.375 absoluteUsedCapacity=0.375 used=<memory:3072, vCores:2> cluster=<memory:8192, vCores:8>
2020-07-29 22:37:57,531 INFO org.apache.hadoop.yarn.server.resourcemanager.scheduler.capacity.CapacityScheduler: Allocation proposal accepted
2020-07-29 22:37:58,368 INFO org.apache.hadoop.yarn.server.resourcemanager.rmcontainer.RMContainerImpl: container_1596049428713_0003_01_000003 Container Transitioned from ALLOCATED to ACQUIRED
2020-07-29 22:37:58,547 INFO org.apache.hadoop.yarn.server.resourcemanager.rmcontainer.RMContainerImpl: container_1596049428713_0003_01_000003 Container Transitioned from ACQUIRED to RUNNING
2020-07-29 22:37:59,375 INFO org.apache.hadoop.yarn.server.resourcemanager.scheduler.AppSchedulingInfo: checking for deactivate of application :application_1596049428713_0003
2020-07-29 22:38:05,616 INFO org.apache.hadoop.yarn.server.resourcemanager.rmapp.attempt.RMAppAttemptImpl: Updating application attempt appattempt_1596049428713_0003_000001 with final state: FINISHING, and exit status: -1000
2020-07-29 22:38:05,616 INFO org.apache.hadoop.yarn.server.resourcemanager.rmapp.attempt.RMAppAttemptImpl: appattempt_1596049428713_0003_000001 State change from RUNNING to FINAL_SAVING on event = UNREGISTERED
2020-07-29 22:38:05,616 INFO org.apache.hadoop.yarn.server.resourcemanager.rmapp.RMAppImpl: Updating application application_1596049428713_0003 with final state: FINISHING
2020-07-29 22:38:05,616 INFO org.apache.hadoop.yarn.server.resourcemanager.rmapp.RMAppImpl: application_1596049428713_0003 State change from RUNNING to FINAL_SAVING on event = ATTEMPT_UNREGISTERED
2020-07-29 22:38:05,617 INFO org.apache.hadoop.yarn.server.resourcemanager.recovery.RMStateStore: Updating info for app: application_1596049428713_0003
2020-07-29 22:38:05,617 INFO org.apache.hadoop.yarn.server.resourcemanager.rmapp.attempt.RMAppAttemptImpl: appattempt_1596049428713_0003_000001 State change from FINAL_SAVING to FINISHING on event = ATTEMPT_UPDATE_SAVED
2020-07-29 22:38:05,617 INFO org.apache.hadoop.yarn.server.resourcemanager.rmapp.RMAppImpl: application_1596049428713_0003 State change from FINAL_SAVING to FINISHING on event = APP_UPDATE_SAVED
2020-07-29 22:38:05,655 INFO org.apache.hadoop.yarn.server.resourcemanager.rmcontainer.RMContainerImpl: container_1596049428713_0003_01_000003 Container Transitioned from RUNNING to COMPLETED
2020-07-29 22:38:05,655 INFO org.apache.hadoop.yarn.server.resourcemanager.RMAuditLogger: USER=yagnasri	OPERATION=AM Released Container	TARGET=SchedulerApp	RESULT=SUCCESS	APPID=application_1596049428713_0003	CONTAINERID=container_1596049428713_0003_01_000003	RESOURCE=<memory:1024, vCores:1>
2020-07-29 22:38:06,629 INFO org.apache.hadoop.yarn.server.resourcemanager.ApplicationMasterService: application_1596049428713_0003 unregistered successfully. 
2020-07-29 22:38:12,084 INFO org.apache.hadoop.yarn.server.resourcemanager.rmcontainer.RMContainerImpl: container_1596049428713_0003_01_000001 Container Transitioned from RUNNING to COMPLETED
2020-07-29 22:38:12,085 INFO org.apache.hadoop.yarn.server.resourcemanager.RMAuditLogger: USER=yagnasri	OPERATION=AM Released Container	TARGET=SchedulerApp	RESULT=SUCCESS	APPID=application_1596049428713_0003	CONTAINERID=container_1596049428713_0003_01_000001	RESOURCE=<memory:2048, vCores:1>
2020-07-29 22:38:12,085 INFO org.apache.hadoop.yarn.server.resourcemanager.ApplicationMasterService: Unregistering app attempt : appattempt_1596049428713_0003_000001
2020-07-29 22:38:12,085 INFO org.apache.hadoop.yarn.server.resourcemanager.security.AMRMTokenSecretManager: Application finished, removing password for appattempt_1596049428713_0003_000001
2020-07-29 22:38:12,085 INFO org.apache.hadoop.yarn.server.resourcemanager.rmapp.attempt.RMAppAttemptImpl: appattempt_1596049428713_0003_000001 State change from FINISHING to FINISHED on event = CONTAINER_FINISHED
2020-07-29 22:38:12,085 INFO org.apache.hadoop.yarn.server.resourcemanager.rmapp.RMAppImpl: application_1596049428713_0003 State change from FINISHING to FINISHED on event = ATTEMPT_FINISHED
2020-07-29 22:38:12,085 INFO org.apache.hadoop.yarn.server.resourcemanager.RMAuditLogger: USER=yagnasri	OPERATION=Application Finished - Succeeded	TARGET=RMAppManager	RESULT=SUCCESS	APPID=application_1596049428713_0003
2020-07-29 22:38:12,086 INFO org.apache.hadoop.yarn.server.resourcemanager.RMAppManager$ApplicationSummary: appId=application_1596049428713_0003,name=word count,user=yagnasri,queue=default,state=FINISHED,trackingUrl=http://yagnasri-VirtualBox:8088/proxy/application_1596049428713_0003/,appMasterHost=yagnasri-VirtualBox,submitTime=1596080257708,startTime=1596080257708,finishTime=1596080285616,finalStatus=SUCCEEDED,memorySeconds=86049,vcoreSeconds=49,preemptedMemorySeconds=0,preemptedVcoreSeconds=0,preemptedAMContainers=0,preemptedNonAMContainers=0,preemptedResources=<memory:0\, vCores:0>,applicationType=MAPREDUCE
2020-07-29 22:38:12,086 INFO org.apache.hadoop.yarn.server.resourcemanager.scheduler.capacity.CapacityScheduler: Application Attempt appattempt_1596049428713_0003_000001 is done. finalState=FINISHED
2020-07-29 22:38:12,086 INFO org.apache.hadoop.yarn.server.resourcemanager.scheduler.AppSchedulingInfo: Application application_1596049428713_0003 requests cleared
2020-07-29 22:38:12,086 INFO org.apache.hadoop.yarn.server.resourcemanager.scheduler.capacity.LeafQueue: Application removed - appId: application_1596049428713_0003 user: yagnasri queue: default #user-pending-applications: 0 #user-active-applications: 0 #queue-pending-applications: 0 #queue-active-applications: 0
2020-07-29 22:38:12,086 INFO org.apache.hadoop.yarn.server.resourcemanager.scheduler.capacity.ParentQueue: Application removed - appId: application_1596049428713_0003 user: yagnasri leaf-queue of parent: root #applications: 0
2020-07-29 22:38:12,091 INFO org.apache.hadoop.yarn.server.resourcemanager.amlauncher.AMLauncher: Cleaning master appattempt_1596049428713_0003_000001
